Traceback (most recent call last):
  File "/home/alexandre/.virtualenvs/enacom/lib/python3.10/site-packages/jupyter_cache/executors/utils.py", line 51, in single_nb_execution
    executenb(
  File "/home/alexandre/.virtualenvs/enacom/lib/python3.10/site-packages/nbclient/client.py", line 1204, in execute
    return NotebookClient(nb=nb, resources=resources, km=km, **kwargs).execute()
  File "/home/alexandre/.virtualenvs/enacom/lib/python3.10/site-packages/nbclient/util.py", line 84, in wrapped
    return just_run(coro(*args, **kwargs))
  File "/home/alexandre/.virtualenvs/enacom/lib/python3.10/site-packages/nbclient/util.py", line 62, in just_run
    return loop.run_until_complete(coro)
  File "/usr/local/lib/python3.10/asyncio/base_events.py", line 641, in run_until_complete
    return future.result()
  File "/home/alexandre/.virtualenvs/enacom/lib/python3.10/site-packages/nbclient/client.py", line 663, in async_execute
    await self.async_execute_cell(
  File "/home/alexandre/.virtualenvs/enacom/lib/python3.10/site-packages/nbclient/client.py", line 965, in async_execute_cell
    await self._check_raise_for_error(cell, cell_index, exec_reply)
  File "/home/alexandre/.virtualenvs/enacom/lib/python3.10/site-packages/nbclient/client.py", line 862, in _check_raise_for_error
    raise CellExecutionError.from_cell_and_msg(cell, exec_reply_content)
nbclient.exceptions.CellExecutionError: An error occurred while executing the following cell:
------------------
base = pd.read_excel('/content/drive/MyDrive/ENACOM/Projeto AES/BDHE_1983 a 2022.xlsx', sheet_name=0)
------------------

[0;31m---------------------------------------------------------------------------[0m
[0;31mNameError[0m                                 Traceback (most recent call last)
Input [0;32mIn [1][0m, in [0;36m<cell line: 1>[0;34m()[0m
[0;32m----> 1[0m base [38;5;241m=[39m [43mpd[49m[38;5;241m.[39mread_excel([38;5;124m'[39m[38;5;124m/content/drive/MyDrive/ENACOM/Projeto AES/BDHE_1983 a 2022.xlsx[39m[38;5;124m'[39m, sheet_name[38;5;241m=[39m[38;5;241m0[39m)

[0;31mNameError[0m: name 'pd' is not defined
NameError: name 'pd' is not defined

